Workbook

Sheet Invertir respuestas
A1: Cambio de postura sin razones claras. | B1: Casi siempre cambio de opinión por presión. | C1: A veces me pasa. | D1: No cambio sin fundamento. | E1: No cambio mi postura sin razones claras.
A2: {=6-CELL("columna",A1)} -> 5 | B2: {=6-CELL("columna",B1)} -> 4 | C2: {=6-CELL("columna",C1)} -> 3 | D2: {=6-CELL("columna",D1)} -> 2 | E2: {=6-CELL("columna",E1)} -> 1
A3: {=INDEX($A$1:$E$1,1,A2)} -> No cambio mi postura sin razones claras. | B3: {=INDEX($A$1:$E$1,1,B2)} -> No cambio sin fundamento. | C3: {=INDEX($A$1:$E$1,1,C2)} -> A veces me pasa. | D3: {=INDEX($A$1:$E$1,1,D2)} -> Casi siempre cambio de opinión por presión. | E3: {=INDEX($A$1:$E$1,1,E2)} -> Cambio de postura sin razones claras.
A7: 3 | B7: 45
A8: 4 | B8: 60
A9: 5 | B9: 75
A10: 6 | B10: 90
A11: 7 | B11: 105
A12: 8 | B12: 120
A13: 9 | B13: 135
A14: 10 | B14: 150

Sheet 150 Preguntas
A1: Item | B1: Pregunta_I | C1: Nivel | D1: CriterioN | E1: P_Invertida | F1: Conciencia | G1: CriterioC | H1: Impacto | I1: Pregunta | J1: R1 | K1: R2 | L1: R3 | M1: R4 | N1: R5 | O1: Tipo de Respuesta | P1: T1 | Q1: T2 | R1: T3 | S1: T4 | T1: T5 | U1: Explicación | V1: Diccionarios | W1: Sorteo | X1: Ranking
A2: 1 | B2: Analizo diferentes perspectivas antes de tomar una decisión | C2: N1 | D2: Fundamento interno que sostiene la conducta social. | E2: false | F2: Cognitiva | G2: Comprensión de problemas sociales. | H2: Medio | I2: ¿Realizas un análisis consciente de las diversas perspectivas de un problema social antes de definir tu conducta frente a los demás? | J2: Actúo por impulso o inercia social. | K2: Reflexiono solo si el tema me afecta. | L2: Evalúo posturas de forma superficial. | M2: Investigo y contrasto opiniones habitualmente. | N2: Mi conducta se basa en un análisis profundo. | O2: Hábito | P2: Nunca | Q2: Casi nunca | R2: A veces | S2: Casi siempre | T2: Siempre | U2: Esta reformulación traslada el análisis de perspectivas a un contexto social y cotidiano, evaluando el hábito de considerar opiniones externas antes de actuar. Esto permite medir apertura cognitiva y disposición a tomar decisiones más conscientes dentro de un entorno colectivo. | V2: ="{"&_xlfn.TEXTJOIN(",",TRUE, """"&_xlfn.TEXTJOIN(""":",TRUE,A$1,A2), """"&_xlfn.TEXTJOIN(""":""",TRUE,B$1,B2)&"""", """"&_xlfn.TEXTJOIN(""":""",TRUE,C$1,C2)&"""", """"&_xlfn.TEXTJOIN(""":""",TRUE,D$1,D2)&"""", """"&_xlfn.TEXTJOIN(""":",TRUE,E$1,E2), """"&_xlfn.TEXTJOIN(""":""",TRUE,F$1,F2)&"""", """"&_xlfn.TEXTJOIN(""":""",TRUE,G$1,G2)&"""", """"&_xlfn.TEXTJOIN(""":""",TRUE,H$1,H2)&"""", """"&_xlfn.TEXTJOIN(""":""",TRUE,I$1,I2)&"""", """"&_xlfn.TEXTJOIN(""":""",TRUE,J$1,J2)&"""", """"&_xlfn.TEXTJOIN(""":""",TRUE,K$1,K2)&"""", """"&_xlfn.TEXTJOIN(""":""",TRUE,L$1,L2)&"""", """"&_xlfn.TEXTJOIN(""":""",TRUE,M$1,M2)&"""", """"&_xlfn.TEXTJOIN(""":""",TRUE,N$1,N2)&"""", """"&_xlfn.TEXTJOIN(""":""",TRUE,O$1,O2)&"""", """"&_xlfn.TEXTJOIN(""":""",TRUE,P$1,P2)&"""", """"&_xlfn.TEXTJOIN(""":""",TRUE,Q$1,Q2)&"""", """"&_xlfn.TEXTJOIN(""":""",TRUE,R$1,R2)&"""", """"&_xlfn.TEXTJOIN(""":""",TRUE,S$1,S2)&"""", """"&_xlfn.TEXTJOIN(""":""",TRUE,T$1,T2)&"""", """"&_xlfn.TEXTJOIN(""":""",TRUE,U$1,U2)&"""" )&"}," -> {"Item":1,"Pregunta_I":" Analizo diferentes perspectivas antes de tomar una decisión","Nivel":"N1","CriterioN":"Fundamento interno que sostiene la conducta social.","P_Invertida":false,"Conciencia":"Cognitiva","CriterioC":"Comprensión de problemas sociales.","Impacto":"Medio","Pregunta":"¿Realizas un análisis consciente de las diversas perspectivas de un problema social antes de definir tu conducta frente a los demás?","R1":"Actúo por impulso o inercia social.","R2":"Reflexiono solo si el tema me afecta.","R3":"Evalúo posturas de forma superficial.","R4":"Investigo y contrasto opiniones habitualmente.","R5":"Mi conducta se basa en un análisis profundo.","Tipo de Respuesta":"Hábito","T1":"Nunca","T2":"Casi nunca","T3":"A veces","T4":"Casi siempre","T5":"Siempre","Explicación":"Esta reformulación traslada el análisis de perspectivas a un contexto social y cotidiano, evaluando el hábito de considerar opiniones externas antes de actuar. Esto permite medir apertura cognitiva y disposición a tomar decisiones más conscientes dentro de un entorno colectivo."}, | W2: =RAND() -> 0.66940806 | X2: =COUNTIFS($F$2:$F$200, F2, $W$2:$W$200, "<=" & W2) -> 7
A3: 2 | B3: Cuestiono la información antes de aceptarla como verdadera | C3: N1 | D3: Fundamento interno que sostiene la conducta social. | E3: false | F3: Cognitiva | G3: Comprensión de problemas sociales. | H3: Medio | I3: ¿Cuestionas y verificas la veracidad de la información sobre problemas sociales antes de aceptarla como una verdad que guíe tu opinión o conducta? | J3: Acepto la información de forma automática. | K3: Solo dudo si la fuente me parece sospechosa. | L3: Comparo datos de vez en cuando antes de decidir. | M3: Suelo verificar la información en distintas fuentes. | N3: Evalúo críticamente toda información antes de creerla. | O3: Hábito | P3: Nunca | Q3: Casi nunca | R3: A veces | S3: Casi siempre | T3: Siempre | U3: La pregunta mide el hábito de pensamiento crítico aplicado al entorno social, especialmente frente a información compartida por otros. Evaluar este comportamiento es relevante porque influye en la forma en que el individuo procesa rumores, noticias o creencias sociales antes de reproducirlas. | V3: ="{"&_xlfn.TEXTJOIN(",",TRUE, """"&_xlfn.TEXTJOIN(""":",TRUE,A$1,A3), """"&_xlfn.TEXTJOIN(""":""",TRUE,B$1,B3)&"""", """"&_xlfn.TEXTJOIN(""":""",TRUE,C$1,C3)&"""", """"&_xlfn.TEXTJOIN(""":""",TRUE,D$1,D3)&"""", """"&_xlfn.TEXTJOIN(""":",TRUE,E$1,E3), """"&_xlfn.TEXTJOIN(""":""",TRUE,F$1,F3)&"""", """"&_xlfn.TEXTJOIN(""":""",TRUE,G$1,G3)&"""", """"&_xlfn.TEXTJOIN(""":""",TRUE,H$1,H3)&"""", """"&_xlfn.TEXTJOIN(""":""",TRUE,I$1,I3)&"""", """"&_xlfn.TEXTJOIN(""":""",TRUE,J$1,J3)&"""", """"&_xlfn.TEXTJOIN(""":""",TRUE,K$1,K3)&"""", """"&_xlfn.TEXTJOIN(""":""",TRUE,L$1,L3)&"""", """"&_xlfn.TEXTJOIN(""":""",TRUE,M$1,M3)&"""", """"&_xlfn.TEXTJOIN(""":""",TRUE,N$1,N3)&"""", """"&_xlfn.TEXTJOIN(""":""",TRUE,O$1,O3)&"""", """"&_xlfn.TEXTJOIN(""":""",TRUE,P$1,P3)&"""", """"&_xlfn.TEXTJOIN(""":""",TRUE,Q$1,Q3)&"""", """"&_xlfn.TEXTJOIN(""":""",TRUE,R$1,R3)&"""", """"&_xlfn.TEXTJOIN(""":""",TRUE,S$1,S3)&"""", """"&_xlfn.TEXTJOIN(""":""",TRUE,T$1,T3)&"""", """"&_xlfn.TEXTJOIN(""":""",TRUE,U$1,U3)&"""" )&"}," -> {"Item":2,"Pregunta_I":" Cuestiono la información antes de aceptarla como verdadera","Nivel":"N1","CriterioN":"Fundamento interno que sostiene la conducta social.","P_Invertida":false,"Conciencia":"Cognitiva","CriterioC":"Comprensión de problemas sociales.","Impacto":"Medio","Pregunta":"¿Cuestionas y verificas la veracidad de la información sobre problemas sociales antes de aceptarla como una verdad que guíe tu opinión o conducta?","R1":"Acepto la información de forma automática.","R2":"Solo dudo si la fuente me parece sospechosa.","R3":"Comparo datos de vez en cuando antes de decidir.","R4":"Suelo verificar la información en distintas fuentes.","R5":"Evalúo críticamente toda información antes de creerla.","Tipo de Respuesta":"Hábito","T1":"Nunca","T2":"Casi nunca","T3":"A veces","T4":"Casi siempre","T5":"Siempre","Explicación":"La pregunta mide el hábito de pensamiento crítico aplicado al entorno social, especialmente frente a información compartida por otros. Evaluar este comportamiento es relevante porque influye en la forma en que el individuo procesa rumores, noticias o creencias sociales antes de reproducirlas."}, | W3: =RAND() -> 0.3710463 | X3: =COUNTIFS($F$2:$F$200, F3, $W$2:$W$200, "<=" & W3) -> 4
A4: 3 | B4: Reflexiono sobre mis propios pensamientos | C4: N1 | D4: Fundamento interno que sostiene la conducta social. | E4: false | F4: Cognitiva | G4: Comprensión de problemas sociales. | H4: Medio | I4: ¿Monitoreas y reflexionas sobre tus propios pensamientos y prejuicios para asegurarte de que tu conducta hacia los demás sea justa y coherente? | J4: Actúo sin cuestionar el origen de mis pensamientos. | K4: Solo reflexiono si alguien señala un error en mi trato. | L4: Intento identificar mis sesgos de manera ocasional. | M4: Suelo revisar mis intenciones antes de actuar. | N4: Evalúo constantemente mis pensamientos para guiar mi conducta. | O4: Conducta | P4: Nunca | Q4: Casi nunca | R4: A veces | S4: Casi siempre | T4: Siempre | U4: Esta formulación sitúa la reflexión interna dentro de un conflicto interpersonal, permitiendo medir la capacidad de autocontrol cognitivo antes de responder socialmente. Se evalúa qué tan fácil es para el individuo detenerse, analizar y responder con conciencia en interacción con otros. | V4: ="{"&_xlfn.TEXTJOIN(",",TRUE, """"&_xlfn.TEXTJOIN(""":",TRUE,A$1,A4), """"&_xlfn.TEXTJOIN(""":""",TRUE,B$1,B4)&"""", """"&_xlfn.TEXTJOIN(""":""",TRUE,C$1,C4)&"""", """"&_xlfn.TEXTJOIN(""":""",TRUE,D$1,D4)&"""", """"&_xlfn.TEXTJOIN(""":",TRUE,E$1,E4), """"&_xlfn.TEXTJOIN(""":""",TRUE,F$1,F4)&"""", """"&_xlfn.TEXTJOIN(""":""",TRUE,G$1,G4)&"""", """"&_xlfn.TEXTJOIN(""":""",TRUE,H$1,H4)&"""", """"&_xlfn.TEXTJOIN(""":""",TRUE,I$1,I4)&"""", """"&_xlfn.TEXTJOIN(""":""",TRUE,J$1,J4)&"""", """"&_xlfn.TEXTJOIN(""":""",TRUE,K$1,K4)&"""", """"&_xlfn.TEXTJOIN(""":""",TRUE,L$1,L4)&"""", """"&_xlfn.TEXTJOIN(""":""",TRUE,M$1,M4)&"""", """"&_xlfn.TEXTJOIN(""":""",TRUE,N$1,N4)&"""", """"&_xlfn.TEXTJOIN(""":""",TRUE,O$1,O4)&"""", """"&_xlfn.TEXTJOIN(""":""",TRUE,P$1,P4)&"""", """"&_xlfn.TEXTJOIN(""":""",TRUE,Q$1,Q4)&"""", """"&_xlfn.TEXTJOIN(""":""",TRUE,R$1,R4)&"""", """"&_xlfn.TEXTJOIN(""":""",TRUE,S$1,S4)&"""", """"&_xlfn.TEXTJOIN(""":""",TRUE,T$1,T4)&"""", """"&_xlfn.TEXTJOIN(""":""",TRUE,U$1,U4)&"""" )&"}," -> {"Item":3,"Pregunta_I":" Reflexiono sobre mis propios pensamientos","Nivel":"N1","CriterioN":"Fundamento interno que sostiene la conducta social.","P_Invertida":false,"Conciencia":"Cognitiva","CriterioC":"Comprensión de problemas sociales.","Impacto":"Medio","Pregunta":"¿Monitoreas y reflexionas sobre tus propios pensamientos y prejuicios para asegurarte de que tu conducta hacia los demás sea justa y coherente?","R1":"Actúo sin cuestionar el origen de mis pensamientos.","R2":"Solo reflexiono si alguien señala un error en mi trato.","R3":"Intento identificar mis sesgos de manera ocasional.","R4":"Suelo revisar mis intenciones antes de actuar.","R5":"Evalúo constantemente mis pensamientos para guiar mi conducta.","Tipo de Respuesta":"Conducta","T1":"Nunca","T2":"Casi nunca","T3":"A veces","T4":"Casi siempre","T5":"Siempre","Explicación":"Esta formulación sitúa la reflexión interna dentro de un conflicto interpersonal, permitiendo medir la capacidad de autocontrol cognitivo antes de responder socialmente. Se evalúa qué tan fácil es para el individuo detenerse, analizar y responder con conciencia en interacción con otros."}, | W4: =RAND() -> 0.75404997 | X4: =COUNTIFS($F$2:$F$200, F4, $W$2:$W$200, "<=" & W4) -> 9
A5: 4 | B5: Identifico errores en mi razonamiento | C5: N1 | D5: Fundamento interno que sostiene la conducta social. | E5: false | F5: Cognitiva | G5: Comprensión de problemas sociales. | H5: Medio | I5: ¿Te resulta fácil detectar una falla o contradicción en tu propia forma de pensar cuando analizas un problema social complejo? | J5: No logro ver errores en mi lógica. | K5: Me cuesta mucho aceptar que mi razonamiento puede estar equivocado. | L5: A veces noto mis errores, pero solo después de que alguien me los señala. | M5: Suelo identificar mis propias contradicciones mientras estoy reflexionando. | N5: Detecto y corrijo mis fallos de razonamiento de manera natural y constante. | O5: Capacidad | P5: Muy difícil | Q5: Dificil | R5: Neutro | S5: Facil | T5: Muy fácil | U5: Esta formulación sitúa la reflexión interna dentro de un conflicto interpersonal, permitiendo medir la capacidad de autocontrol cognitivo antes de responder socialmente. Se evalúa qué tan fácil es para el individuo detenerse, analizar y responder con conciencia en interacción con otros. | V5: ="{"&_xlfn.TEXTJOIN(",",TRUE, """"&_xlfn.TEXTJOIN(""":",TRUE,A$1,A5), """"&_xlfn.TEXTJOIN(""":""",TRUE,B$1,B5)&"""", """"&_xlfn.TEXTJOIN(""":""",TRUE,C$1,C5)&"""", """"&_xlfn.TEXTJOIN(""":""",TRUE,D$1,D5)&"""", """"&_xlfn.TEXTJOIN(""":",TRUE,E$1,E5), """"&_xlfn.TEXTJOIN(""":""",TRUE,F$1,F5)&"""", """"&_xlfn.TEXTJOIN(""":""",TRUE,G$1,G5)&"""", """"&_xlfn.TEXTJOIN(""":""",TRUE,H$1,H5)&"""", """"&_xlfn.TEXTJOIN(""":""",TRUE,I$1,I5)&"""", """"&_xlfn.TEXTJOIN(""":""",TRUE,J$1,J5)&"""", """"&_xlfn.TEXTJOIN(""":""",TRUE,K$1,K5)&"""", """"&_xlfn.TEXTJOIN(""":""",TRUE,L$1,L5)&"""", """"&_xlfn.TEXTJOIN(""":""",TRUE,M$1,M5)&"""", """"&_xlfn.TEXTJOIN(""":""",TRUE,N$1,N5)&"""", """"&_xlfn.TEXTJOIN(""":""",TRUE,O$1,O5)&"""", """"&_xlfn.TEXTJOIN(""":""",TRUE,P$1,P5)&"""", """"&_xlfn.TEXTJOIN(""":""",TRUE,Q$1,Q5)&"""", """"&_xlfn.TEXTJOIN(""":""",TRUE,R$1,R5)&"""", """"&_xlfn.TEXTJOIN(""":""",TRUE,S$1,S5)&"""", """"&_xlfn.TEXTJOIN(""":""",TRUE,T$1,T5)&"""", """"&_xlfn.TEXTJOIN(""":""",TRUE,U$1,U5)&"""" )&"}," -> {"Item":4,"Pregunta_I":" Identifico errores en mi razonamiento","Nivel":"N1","CriterioN":"Fundamento interno que sostiene la conducta social.","P_Invertida":false,"Conciencia":"Cognitiva","CriterioC":"Comprensión de problemas sociales.","Impacto":"Medio","Pregunta":"¿Te resulta fácil detectar una falla o contradicción en tu propia forma de pensar cuando analizas un problema social complejo?","R1":"No logro ver errores en mi lógica.","R2":"Me cuesta mucho aceptar que mi razonamiento puede estar equivocado.","R3":"A veces noto mis errores, pero solo después de que alguien me los señala.","R4":"Suelo identificar mis propias contradicciones mientras estoy reflexionando.","R5":"Detecto y corrijo mis fallos de razonamiento de manera natural y constante.","Tipo de Respuesta":"Capacidad","T1":"Muy difícil","T2":"Dificil","T3":"Neutro","T4":"Facil","T5":"Muy fácil","Explicación":"Esta formulación sitúa la reflexión interna dentro de un conflicto interpersonal, permitiendo medir la capacidad de autocontrol cognitivo antes de responder socialmente. Se evalúa qué tan fácil es para el individuo detenerse, analizar y responder con conciencia en interacción con otros."}, | W5: =RAND() -> 0.13845234 | X5: =COUNTIFS($F$2:$F$200, F5, $W$2:$W$200, "<=" & W5) -> 3
A6: 5 | B6: Busco coherencia lógica en lo que pienso | C6: N1 | D6: Fundamento interno que sostiene la conducta social. | E6: false | F6: Cognitiva | G6: Comprensión de problemas sociales. | H6: Medio | I6: ¿Te resulta fácil asegurar que tus opiniones sobre problemas sociales tengan una base lógica y no se contradigan entre sí? | J6: No suelo revisar si mis ideas tienen lógica o se contradicen. | K6: Me cuesta conectar mis pensamientos de forma coherente. | L6: A veces detecto contradicciones, pero no siempre las corrijo. | M6: Normalmente logro que mis argumentos sociales sean lógicos. | N6: Mantengo una coherencia total en mis ideas de forma natural. | O6: Capacidad | P6: Muy difícil | Q6: Dificil | R6: Neutro | S6: Facil | T6: Muy fácil | U6: Esta reformulación mide la capacidad de mantener coherencia lógica al comunicarse con otros, lo cual impacta directamente en la claridad del pensamiento y la interacción social. Permite evaluar si el individuo organiza sus argumentos antes de expresarse dentro de un entorno colectivo. | V6: ="{"&_xlfn.TEXTJOIN(",",TRUE, """"&_xlfn.TEXTJOIN(""":",TRUE,A$1,A6), """"&_xlfn.TEXTJOIN(""":""",TRUE,B$1,B6)&"""", """"&_xlfn.TEXTJOIN(""":""",TRUE,C$1,C6)&"""", """"&_xlfn.TEXTJOIN(""":""",TRUE,D$1,D6)&"""", """"&_xlfn.TEXTJOIN(""":",TRUE,E$1,E6), """"&_xlfn.TEXTJOIN(""":""",TRUE,F$1,F6)&"""", """"&_xlfn.TEXTJOIN(""":""",TRUE,G$1,G6)&"""", """"&_xlfn.TEXTJOIN(""":""",TRUE,H$1,H6)&"""", """"&_xlfn.TEXTJOIN(""":""",TRUE,I$1,I6)&"""", """"&_xlfn.TEXTJOIN(""":""",TRUE,J$1,J6)&"""", """"&_xlfn.TEXTJOIN(""":""",TRUE,K$1,K6)&"""", """"&_xlfn.TEXTJOIN(""":""",TRUE,L$1,L6)&"""", """"&_xlfn.TEXTJOIN(""":""",TRUE,M$1,M6)&"""", """"&_xlfn.TEXTJOIN(""":""",TRUE,N$1,N6)&"""", """"&_xlfn.TEXTJOIN(""":""",TRUE,O$1,O6)&"""", """"&_xlfn.TEXTJOIN(""":""",TRUE,P$1,P6)&"""", """"&_xlfn.TEXTJOIN(""":""",TRUE,Q$1,Q6)&"""", """"&_xlfn.TEXTJOIN(""":""",TRUE,R$1,R6)&"""", """"&_xlfn.TEXTJOIN(""":""",TRUE,S$1,S6)&"""", """"&_xlfn.TEXTJOIN(""":""",TRUE,T$1,T6)&"""", """"&_xlfn.TEXTJOIN(""":""",TRUE,U$1,U6)&"""" )&"}," -> {"Item":5,"Pregunta_I":" Busco coherencia lógica en lo que pienso","Nivel":"N1","CriterioN":"Fundamento interno que sostiene la conducta social.","P_Invertida":false,"Conciencia":"Cognitiva","CriterioC":"Comprensión de problemas sociales.","Impacto":"Medio","Pregunta":"¿Te resulta fácil asegurar que tus opiniones sobre problemas sociales tengan una base lógica y no se contradigan entre sí?","R1":"No suelo revisar si mis ideas tienen lógica o se contradicen.","R2":"Me cuesta conectar mis pensamientos de forma coherente.","R3":"A veces detecto contradicciones, pero no siempre las corrijo.","R4":"Normalmente logro que mis argumentos sociales sean lógicos.","R5":"Mantengo una coherencia total en mis ideas de forma natural.","Tipo de Respuesta":"Capacidad","T1":"Muy difícil","T2":"Dificil","T3":"Neutro","T4":"Facil","T5":"Muy fácil","Explicación":"Esta reformulación mide la capacidad de mantener coherencia lógica al comunicarse con otros, lo cual impacta directamente en la claridad del pensamiento y la interacción social. Permite evaluar si el individuo organiza sus argumentos antes de expresarse dentro de un entorno colectivo."}, | W6: =RAND() -> 0.68455663 | X6: =COUNTIFS($F$2:$F$200, F6, $W$2:$W$200, "<=" & W6) -> 8
A7: 6 | B7: Cambio de opinión cuando la evidencia lo justifica | C7: N1 | D7: Fundamento interno que sostiene la conducta social. | E7: false | F7: Cognitiva | G7: Comprensión de problemas sociales. | H7: Medio | I7: ¿Qué tan de acuerdo estás con la práctica de modificar tu postura sobre un problema social cuando se te presenta evidencia lógica que demuestra que tu opinión inicial era incorrecta? | J7: Mantengo mi posición inicial aunque me presenten pruebas en contra. | K7: Me cuesta mucho aceptar que estoy equivocado y cambiar mi discurso. | L7: Solo cambio de opinión si la evidencia es abrumadora o me afecta. | M7: Estoy dispuesto a ajustar mis ideas si me demuestran que hay datos más válidos. | N7: Priorizo la verdad y la lógica sobre el hecho de tener la razón. | O7: Acuerdo | P7: Totalmente en desacuerdo | Q7: En desacuerdo | R7: Ni de acuerdo ni en desacuerdo | S7: De acuerdo | T7: Totalmente de acuerdo | U7: La pregunta evalúa el nivel de acuerdo con la capacidad de ajustar creencias cuando existen argumentos sólidos. Esto permite medir apertura cognitiva y disposición al cambio racional, habilidades esenciales para la toma de decisiones responsables dentro de dinámicas sociales. | V7: ="{"&_xlfn.TEXTJOIN(",",TRUE, """"&_xlfn.TEXTJOIN(""":",TRUE,A$1,A7), """"&_xlfn.TEXTJOIN(""":""",TRUE,B$1,B7)&"""", """"&_xlfn.TEXTJOIN(""":""",TRUE,C$1,C7)&"""", """"&_xlfn.TEXTJOIN(""":""",TRUE,D$1,D7)&"""", """"&_xlfn.TEXTJOIN(""":",TRUE,E$1,E7), """"&_xlfn.TEXTJOIN(""":""",TRUE,F$1,F7)&"""", """"&_xlfn.TEXTJOIN(""":""",TRUE,G$1,G7)&"""", """"&_xlfn.TEXTJOIN(""":""",TRUE,H$1,H7)&"""", """"&_xlfn.TEXTJOIN(""":""",TRUE,I$1,I7)&"""", """"&_xlfn.TEXTJOIN(""":""",TRUE,J$1,J7)&"""", """"&_xlfn.TEXTJOIN(""":""",TRUE,K$1,K7)&"""", """"&_xlfn.TEXTJOIN(""":""",TRUE,L$1,L7)&"""", """"&_xlfn.TEXTJOIN(""":""",TRUE,M$1,M7)&"""", """"&_xlfn.TEXTJOIN(""":""",TRUE,N$1,N7)&"""", """"&_xlfn.TEXTJOIN(""":""",TRUE,O$1,O7)&"""", """"&_xlfn.TEXTJOIN(""":""",TRUE,P$1,P7)&"""", """"&_xlfn.TEXTJOIN(""":""",TRUE,Q$1,Q7)&"""", """"&_xlfn.TEXTJOIN(""":""",TRUE,R$1,R7)&"""", """"&_xlfn.TEXTJOIN(""":""",TRUE,S$1,S7)&"""", """"&_xlfn.TEXTJOIN(""":""",TRUE,T$1,T7)&"""", """"&_xlfn.TEXTJOIN(""":""",TRUE,U$1,U7)&"""" )&"}," -> {"Item":6,"Pregunta_I":" Cambio de opinión cuando la evidencia lo justifica","Nivel":"N1","CriterioN":"Fundamento interno que sostiene la conducta social.","P_Invertida":false,"Conciencia":"Cognitiva","CriterioC":"Comprensión de problemas sociales.","Impacto":"Medio","Pregunta":"¿Qué tan de acuerdo estás con la práctica de modificar tu postura sobre un problema social cuando se te presenta evidencia lógica que demuestra que tu opinión inicial era incorrecta?","R1":"Mantengo mi posición inicial aunque me presenten pruebas en contra.","R2":"Me cuesta mucho aceptar que estoy equivocado y cambiar mi discurso.","R3":"Solo cambio de opinión si la evidencia es abrumadora o me afecta.","R4":"Estoy dispuesto a ajustar mis ideas si me demuestran que hay datos más válidos.","R5":"Priorizo la verdad y la lógica sobre el hecho de tener la razón.","Tipo de Respuesta":"Acuerdo","T1":"Totalmente en desacuerdo","T2":"En desacuerdo","T3":"Ni de acuerdo ni en desacuerdo","T4":"De acuerdo","T5":"Totalmente de acuerdo","Explicación":"La pregunta evalúa el nivel de acuerdo con la capacidad de ajustar creencias cuando existen argumentos sólidos. Esto permite medir apertura cognitiva y disposición al cambio racional, habilidades esenciales para la toma de decisiones responsables dentro de dinámicas sociales."}, | W7: =RAND() -> 0.58881641 | X7: =COUNTIFS($F$2:$F$200, F7, $W$2:$W$200, "<=" & W7) -> 5
A8: 7 | B8: Me dejo llevar por ideas sin analizarlas | C8: N1 | D8: Fundamento interno que sostiene la conducta social. | E8: true | F8: Cognitiva | G8: Comprensión de problemas sociales. | H8: Medio | I8: ¿Adoptas ideas sociales solo porque todos las comparten, sin analizarlas tú mismo? | J8: Siempre analizo antes de aceptar. | K8: Trato de reflexionar. | L8: Me dejo llevar en temas comunes. | M8: Sigo la corriente habitualmente. | N8: Acepto lo que dicen sin cuestionarlo. | O8: Hábito | P8: Nunca | Q8: Casi nunca | R8: A veces | S8: Casi siempre | T8: Siempre | U8: Esta pregunta analiza el hábito de aceptar tendencias sociales sin reflexión crítica, midiendo influencia social y autonomía cognitiva. Es útil para identificar qué tan frecuentemente el individuo adopta ideas colectivas sin cuestionar su coherencia o impacto. | V8: ="{"&_xlfn.TEXTJOIN(",",TRUE, """"&_xlfn.TEXTJOIN(""":",TRUE,A$1,A8), """"&_xlfn.TEXTJOIN(""":""",TRUE,B$1,B8)&"""", """"&_xlfn.TEXTJOIN(""":""",TRUE,C$1,C8)&"""", """"&_xlfn.TEXTJOIN(""":""",TRUE,D$1,D8)&"""", """"&_xlfn.TEXTJOIN(""":",TRUE,E$1,E8), """"&_xlfn.TEXTJOIN(""":""",TRUE,F$1,F8)&"""", """"&_xlfn.TEXTJOIN(""":""",TRUE,G$1,G8)&"""", """"&_xlfn.TEXTJOIN(""":""",TRUE,H$1,H8)&"""", """"&_xlfn.TEXTJOIN(""":""",TRUE,I$1,I8)&"""", """"&_xlfn.TEXTJOIN(""":""",TRUE,J$1,J8)&"""", """"&_xlfn.TEXTJOIN(""":""",TRUE,K$1,K8)&"""", """"&_xlfn.TEXTJOIN(""":""",TRUE,L$1,L8)&"""", """"&_xlfn.TEXTJOIN(""":""",TRUE,M$1,M8)&"""", """"&_xlfn.TEXTJOIN(""":""",TRUE,N$1,N8)&"""", """"&_xlfn.TEXTJOIN(""":""",TRUE,O$1,O8)&"""", """"&_xlfn.TEXTJOIN(""":""",TRUE,P$1,P8)&"""", """"&_xlfn.TEXTJOIN(""":""",TRUE,Q$1,Q8)&"""", """"&_xlfn.TEXTJOIN(""":""",TRUE,R$1,R8)&"""", """"&_xlfn.TEXTJOIN(""":""",TRUE,S$1,S8)&"""", """"&_xlfn.TEXTJOIN(""":""",TRUE,T$1,T8)&"""", """"&_xlfn.TEXTJOIN(""":""",TRUE,U$1,U8)&"""" )&"}," -> {"Item":7,"Pregunta_I":" Me dejo llevar por ideas sin analizarlas","Nivel":"N1","CriterioN":"Fundamento interno que sostiene la conducta social.","P_Invertida":true,"Conciencia":"Cognitiva","CriterioC":"Comprensión de problemas sociales.","Impacto":"Medio","Pregunta":"¿Adoptas ideas sociales solo porque todos las comparten, sin analizarlas tú mismo?","R1":"Siempre analizo antes de aceptar.","R2":"Trato de reflexionar.","R3":"Me dejo llevar en temas comunes.","R4":"Sigo la corriente habitualmente.","R5":"Acepto lo que dicen sin cuestionarlo.","Tipo de Respuesta":"Hábito","T1":"Nunca","T2":"Casi nunca","T3":"A veces","T4":"Casi siempre","T5":"Siempre","Explicación":"Esta pregunta analiza el hábito de aceptar tendencias sociales sin reflexión crítica, midiendo influencia social y autonomía cognitiva. Es útil para identificar qué tan frecuentemente el individuo adopta ideas colectivas sin cuestionar su coherencia o impacto."}, | W8: =RAND() -> 0.65699592 | X8: =COUNTIFS($F$2:$F$200, F8, $W$2:$W$200, "<=" & W8) -> 6
A9: 8 | B9: Evalúo consecuencias antes de actuar | C9: N1 | D9: Fundamento interno que sostiene la conducta social. | E9: false | F9: Cognitiva | G9: Comprensión de problemas sociales. | H9: Medio | I9: ¿Te resulta fácil prever el impacto social de tus acciones antes de decidir cómo actuar? | J9: Actúo sin pensar en las consecuencias. | K9: Me cuesta imaginar cómo afectarán mis actos a otros. | L9: Solo evalúo consecuencias en situaciones graves. | M9: Suelo anticipar el efecto social de lo que hago. | N9: Proyecto siempre el impacto de mis actos con claridad. | O9: Capacidad | P9: Muy difícil | Q9: Dificil | R9: Neutro | S9: Facil | T9: Muy fácil | U9: La pregunta mide la capacidad de anticipar consecuencias sociales antes de actuar o hablar, evaluando pensamiento preventivo y responsabilidad cognitiva. Las respuestas permiten identificar si la persona regula su conducta considerando el efecto que genera en otros. | V9: ="{"&_xlfn.TEXTJOIN(",",TRUE, """"&_xlfn.TEXTJOIN(""":",TRUE,A$1,A9), """"&_xlfn.TEXTJOIN(""":""",TRUE,B$1,B9)&"""", """"&_xlfn.TEXTJOIN(""":""",TRUE,C$1,C9)&"""", """"&_xlfn.TEXTJOIN(""":""",TRUE,D$1,D9)&"""", """"&_xlfn.TEXTJOIN(""":",TRUE,E$1,E9), """"&_xlfn.TEXTJOIN(""":""",TRUE,F$1,F9)&"""", """"&_xlfn.TEXTJOIN(""":""",TRUE,G$1,G9)&"""", """"&_xlfn.TEXTJOIN(""":""",TRUE,H$1,H9)&"""", """"&_xlfn.TEXTJOIN(""":""",TRUE,I$1,I9)&"""", """"&_xlfn.TEXTJOIN(""":""",TRUE,J$1,J9)&"""", """"&_xlfn.TEXTJOIN(""":""",TRUE,K$1,K9)&"""", """"&_xlfn.TEXTJOIN(""":""",TRUE,L$1,L9)&"""", """"&_xlfn.TEXTJOIN(""":""",TRUE,M$1,M9)&"""", """"&_xlfn.TEXTJOIN(""":""",TRUE,N$1,N9)&"""", """"&_xlfn.TEXTJOIN(""":""",TRUE,O$1,O9)&"""", """"&_xlfn.TEXTJOIN(""":""",TRUE,P$1,P9)&"""", """"&_xlfn.TEXTJOIN(""":""",TRUE,Q$1,Q9)&"""", """"&_xlfn.TEXTJOIN(""":""",TRUE,R$1,R9)&"""", """"&_xlfn.TEXTJOIN(""":""",TRUE,S$1,S9)&"""", """"&_xlfn.TEXTJOIN(""":""",TRUE,T$1,T9)&"""", """"&_xlfn.TEXTJOIN(""":""",TRUE,U$1,U9)&"""" )&"}," -> {"Item":8,"Pregunta_I":" Evalúo consecuencias antes de actuar","Nivel":"N1","CriterioN":"Fundamento interno que sostiene la conducta social.","P_Invertida":false,"Conciencia":"Cognitiva","CriterioC":"Comprensión de problemas sociales.","Impacto":"Medio","Pregunta":"¿Te resulta fácil prever el impacto social de tus acciones antes de decidir cómo actuar?","R1":"Actúo sin pensar en las consecuencias.","R2":"Me cuesta imaginar cómo afectarán mis actos a otros.","R3":"Solo evalúo consecuencias en situaciones graves.","R4":"Suelo anticipar el efecto social de lo que hago.","R5":"Proyecto siempre el impacto de mis actos con claridad.","Tipo de Respuesta":"Capacidad","T1":"Muy difícil","T2":"Dificil","T3":"Neutro","T4":"Facil","T5":"Muy fácil","Explicación":"La pregunta mide la capacidad de anticipar consecuencias sociales antes de actuar o hablar, evaluando pensamiento preventivo y responsabilidad cognitiva. Las respuestas permiten identificar si la persona regula su conducta considerando el efecto que genera en otros."}, | W9: =RAND() -> 0.92160152 | X9: =COUNTIFS($F$2:$F$200, F9, $W$2:$W$200, "<=" & W9) -> 10
A10: 9 | B10: Organizo mentalmente la información compleja | C10: N1 | D10: Fundamento interno que sostiene la conducta social. | E10: false | F10: Cognitiva | G10: Comprensión de problemas sociales. | H10: Medio | I10: ¿Te resulta fácil ordenar mentalmente los diferentes datos y factores que componen un problema social complejo? | J10: La información me abruma y no logro estructurarla. | K10: Me cuesta conectar los puntos para entender el problema. | L10: Organizo la información si es sencilla o conocida. | M10: Suelo esquematizar mentalmente las partes del problema. | N10: Clarifico y estructuro datos complejos con naturalidad. | O10: Capacidad | P10: Muy difícil | Q10: Dificil | R10: Neutro | S10: Facil | T10: Muy fácil | U10: Esta formulación evalúa la capacidad de procesar múltiples perspectivas en una conversación, midiendo organización mental y comprensión situacional. Es importante porque refleja cómo el individuo estructura información social compleja para actuar con claridad y criterio. | V10: ="{"&_xlfn.TEXTJOIN(",",TRUE, """"&_xlfn.TEXTJOIN(""":",TRUE,A$1,A10), """"&_xlfn.TEXTJOIN(""":""",TRUE,B$1,B10)&"""", """"&_xlfn.TEXTJOIN(""":""",TRUE,C$1,C10)&"""", """"&_xlfn.TEXTJOIN(""":""",TRUE,D$1,D10)&"""", """"&_xlfn.TEXTJOIN(""":",TRUE,E$1,E10), """"&_xlfn.TEXTJOIN(""":""",TRUE,F$1,F10)&"""", """"&_xlfn.TEXTJOIN(""":""",TRUE,G$1,G10)&"""", """"&_xlfn.TEXTJOIN(""":""",TRUE,H$1,H10)&"""", """"&_xlfn.TEXTJOIN(""":""",TRUE,I$1,I10)&"""", """"&_xlfn.TEXTJOIN(""":""",TRUE,J$1,J10)&"""", """"&_xlfn.TEXTJOIN(""":""",TRUE,K$1,K10)&"""", """"&_xlfn.TEXTJOIN(""":""",TRUE,L$1,L10)&"""", """"&_xlfn.TEXTJOIN(""":""",TRUE,M$1,M10)&"""", """"&_xlfn.TEXTJOIN(""":""",TRUE,N$1,N10)&"""", """"&_xlfn.TEXTJOIN(""":""",TRUE,O$1,O10)&"""", """"&_xlfn.TEXTJOIN(""":""",TRUE,P$1,P10)&"""", """"&_xlfn.TEXTJOIN(""":""",TRUE,Q$1,Q10)&"""", """"&_xlfn.TEXTJOIN(""":""",TRUE,R$1,R10)&"""", """"&_xlfn.TEXTJOIN(""":""",TRUE,S$1,S10)&"""", """"&_xlfn.TEXTJOIN(""":""",TRUE,T$1,T10)&"""", """"&_xlfn.TEXTJOIN(""":""",TRUE,U$1,U10)&"""" )&"}," -> {"Item":9,"Pregunta_I":" Organizo mentalmente la información compleja","Nivel":"N1","CriterioN":"Fundamento interno que sostiene la conducta social.","P_Invertida":false,"Conciencia":"Cognitiva","CriterioC":"Comprensión de problemas sociales.","Impacto":"Medio","Pregunta":"¿Te resulta fácil ordenar mentalmente los diferentes datos y factores que componen un problema social complejo?","R1":"La información me abruma y no logro estructurarla.","R2":"Me cuesta conectar los puntos para entender el problema.","R3":"Organizo la información si es sencilla o conocida.","R4":"Suelo esquematizar mentalmente las partes del problema.","R5":"Clarifico y estructuro datos complejos con naturalidad.","Tipo de Respuesta":"Capacidad","T1":"Muy difícil","T2":"Dificil","T3":"Neutro","T4":"Facil","T5":"Muy fácil","Explicación":"Esta formulación evalúa la capacidad de procesar múltiples perspectivas en una conversación, midiendo organización mental y comprensión situacional. Es importante porque refleja cómo el individuo estructura información social compleja para actuar con claridad y criterio."}, | W10: =RAND() -> 0.13626685 | X10: =COUNTIFS($F$2:$F$200, F10, $W$2:$W$200, "<=" & W10) -> 2
A11: 10 | B11: Me cuesta estructurar mis pensamientos | C11: N1 | D11: Fundamento interno que sostiene la conducta social. | E11: true | F11: Cognitiva | G11: Comprensión de problemas sociales. | H11: Medio | I11: ¿Te resulta fácil sentir que tus pensamientos sobre un tema social están desordenados o te cuesta darles una estructura clara? | J11: Mis pensamientos siempre están ordenados y claros. | K11: Logro estructurar bien mis ideas. | L11: A veces me confundo con tanta información. | M11: Frecuentemente me cuesta organizar lo que pienso. | N11: Mis ideas suelen ser un caos y no logro ordenarlas. | O11: Capacidad | P11: Muy difícil | Q11: Dificil | R11: Neutro | S11: Facil | T11: Muy fácil | U11: La pregunta evalúa la dificultad para estructurar pensamientos al comunicarse socialmente, enfocándose en la claridad mental aplicada a la interacción con otros. Al ser una pregunta invertida, permite detectar limitaciones cognitivas en expresión y coherencia verbal en contextos colectivos. | V11: ="{"&_xlfn.TEXTJOIN(",",TRUE, """"&_xlfn.TEXTJOIN(""":",TRUE,A$1,A11), """"&_xlfn.TEXTJOIN(""":""",TRUE,B$1,B11)&"""", """"&_xlfn.TEXTJOIN(""":""",TRUE,C$1,C11)&"""", """"&_xlfn.TEXTJOIN(""":""",TRUE,D$1,D11)&"""", """"&_xlfn.TEXTJOIN(""":",TRUE,E$1,E11), """"&_xlfn.TEXTJOIN(""":""",TRUE,F$1,F11)&"""", """"&_xlfn.TEXTJOIN(""":""",TRUE,G$1,G11)&"""", """"&_xlfn.TEXTJOIN(""":""",TRUE,H$1,H11)&"""", """"&_xlfn.TEXTJOIN(""":""",TRUE,I$1,I11)&"""", """"&_xlfn.TEXTJOIN(""":""",TRUE,J$1,J11)&"""", """"&_xlfn.TEXTJOIN(""":""",TRUE,K$1,K11)&"""", """"&_xlfn.TEXTJOIN(""":""",TRUE,L$1,L11)&"""", """"&_xlfn.TEXTJOIN(""":""",TRUE,M$1,M11)&"""", """"&_xlfn.TEXTJOIN(""":""",TRUE,N$1,N11)&"""", """"&_xlfn.TEXTJOIN(""":""",TRUE,O$1,O11)&"""", """"&_xlfn.TEXTJOIN(""":""",TRUE,P$1,P11)&"""", """"&_xlfn.TEXTJOIN(""":""",TRUE,Q$1,Q11)&"""", """"&_xlfn.TEXTJOIN(""":""",TRUE,R$1,R11)&"""", """"&_xlfn.TEXTJOIN(""":""",TRUE,S$1,S11)&"""", """"&_xlfn.TEXTJOIN(""":""",TRUE,T$1,T11)&"""", """"&_xlfn.TEXTJOIN(""":""",TRUE,U$1,U11)&"""" )&"}," -> {"Item":10,"Pregunta_I":" Me cuesta estructurar mis pensamientos","Nivel":"N1","CriterioN":"Fundamento interno que sostiene la conducta social.","P_Invertida":true,"Conciencia":"Cognitiva","CriterioC":"Comprensión de problemas sociales.","Impacto":"Medio","Pregunta":"¿Te resulta fácil sentir que tus pensamientos sobre un tema social están desordenados o te cuesta darles una estructura clara?","R1":"Mis pensamientos siempre están ordenados y claros.","R2":"Logro estructurar bien mis ideas.","R3":"A veces me confundo con tanta información.","R4":"Frecuentemente me cuesta organizar lo que pienso.","R5":"Mis ideas suelen ser un caos y no logro ordenarlas.","Tipo de Respuesta":"Capacidad","T1":"Muy difícil","T2":"Dificil","T3":"Neutro","T4":"Facil","T5":"Muy fácil","Explicación":"La pregunta evalúa la dificultad para estructurar pensamientos al comunicarse socialmente, enfocándose en la claridad mental aplicada a la interacción con otros. Al ser una pregunta invertida, permite detectar limitaciones cognitivas en expresión y coherencia verbal en contextos colectivos."}, | W11: =RAND() -> 0.011072265 | X11: =COUNTIFS($F$2:$F$200, F11, $W$2:$W$200, "<=" & W11) -> 1
A12: 11 | B12: Identifico con claridad lo que siento | C12: N2 | D12: Procesamiento intermedio que regula y modula. | E12: false | F12: Emocional | G12: Sensibilidad hacia los demás. | H12: Medio | I12: ¿Te resulta fácil identificar con claridad tus emociones cuando te enfrentas a una situación social que te genera sensibilidad o conflicto? | J12: No distingo lo que siento; mis emociones me confunden. | K12: Sé que algo me afecta, pero me cuesta ponerle nombre. | L12: Identifico mis emociones básicas tras un tiempo de reflexión. | M12: Suelo reconocer mis sentimientos con rapidez y claridad. | N12: Noto y comprendo mis emociones al instante en cualquier situación. | O12: Capacidad | P12: Muy difícil | Q12: Dificil | R12: Neutro | S12: Facil | T12: Muy fácil | U12: Se adapta la pregunta al contexto social, manteniendo el objetivo de evaluar conciencia emocional interna. Las respuestas representan niveles de reconocimiento emocional que influyen en la forma en que el individuo responde ante otras personas. | V12: ="{"&_xlfn.TEXTJOIN(",",TRUE, """"&_xlfn.TEXTJOIN(""":",TRUE,A$1,A12), """"&_xlfn.TEXTJOIN(""":""",TRUE,B$1,B12)&"""", """"&_xlfn.TEXTJOIN(""":""",TRUE,C$1,C12)&"""", """"&_xlfn.TEXTJOIN(""":""",TRUE,D$1,D12)&"""", """"&_xlfn.TEXTJOIN(""":",TRUE,E$1,E12), """"&_xlfn.TEXTJOIN(""":""",TRUE,F$1,F12)&"""", """"&_xlfn.TEXTJOIN(""":""",TRUE,G$1,G12)&"""", """"&_xlfn.TEXTJOIN(""":""",TRUE,H$1,H12)&"""", """"&_xlfn.TEXTJOIN(""":""",TRUE,I$1,I12)&"""", """"&_xlfn.TEXTJOIN(""":""",TRUE,J$1,J12)&"""", """"&_xlfn.TEXTJOIN(""":""",TRUE,K$1,K12)&"""", """"&_xlfn.TEXTJOIN(""":""",TRUE,L$1,L12)&"""", """"&_xlfn.TEXTJOIN(""":""",TRUE,M$1,M12)&"""", """"&_xlfn.TEXTJOIN(""":""",TRUE,N$1,N12)&"""", """"&_xlfn.TEXTJOIN(""":""",TRUE,O$1,O12)&"""", """"&_xlfn.TEXTJOIN(""":""",TRUE,P$1,P12)&"""", """"&_xlfn.TEXTJOIN(""":""",TRUE,Q$1,Q12)&"""", """"&_xlfn.TEXTJOIN(""":""",TRUE,R$1,R12)&"""", """"&_xlfn.TEXTJOIN(""":""",TRUE,S$1,S12)&"""", """"&_xlfn.TEXTJOIN(""":""",TRUE,T$1,T12)&"""", """"&_xlfn.TEXTJOIN(""":""",TRUE,U$1,U12)&"""" )&"}," -> {"Item":11,"Pregunta_I":" Identifico con claridad lo que siento","Nivel":"N2","CriterioN":"Procesamiento intermedio que regula y modula.","P_Invertida":false,"Conciencia":"Emocional","CriterioC":"Sensibilidad hacia los demás.","Impacto":"Medio","Pregunta":"¿Te resulta fácil identificar con claridad tus emociones cuando te enfrentas a una situación social que te genera sensibilidad o conflicto?","R1":"No distingo lo que siento; mis emociones me confunden.","R2":"Sé que algo me afecta, pero me cuesta ponerle nombre.","R3":"Identifico mis emociones básicas tras un tiempo de reflexión.","R4":"Suelo reconocer mis sentimientos con rapidez y claridad.","R5":"Noto y comprendo mis emociones al instante en cualquier situación.","Tipo de Respuesta":"Capacidad","T1":"Muy difícil","T2":"Dificil","T3":"Neutro","T4":"Facil","T5":"Muy fácil","Explicación":"Se adapta la pregunta al contexto social, manteniendo el objetivo de evaluar conciencia emocional interna. Las respuestas representan niveles de reconocimiento emocional que influyen en la forma en que el individuo responde ante otras personas."}, | W12: =RAND() -> 0.59990051 | X12: =COUNTIFS($F$2:$F$200, F12, $W$2:$W$200, "<=" & W12) -> 5
A13: 12 | B13: Comprendo por qué me siento como me siento | C13: N2 | D13: Procesamiento intermedio que regula y modula. | E13: false | F13: Emocional | G13: Sensibilidad hacia los demás. | H13: Medio | I13: ¿Te resulta fácil entender la razón exacta de tu malestar o incomodidad cuando te encuentras en un entorno social? | J13: Siento la incomodidad pero no logro entender por qué me ocurre. | K13: Me cuesta mucho descifrar qué detonó mi malestar en ese momento. | L13: A veces comprendo el origen de mi incomodidad tras pensarlo mucho. | M13: Suelo identificar rápido qué situación o comentario me hizo sentir mal. | N13: Reconozco de inmediato la causa exacta de mi emoción social. | O13: Capacidad | P13: Muy difícil | Q13: Dificil | R13: Neutro | S13: Facil | T13: Muy fácil | U13: Se enfoca en la comprensión emocional y su origen, clave para regulación social. Las respuestas miden el nivel de interpretación emocional y autoconocimiento, necesario para actuar con mayor equilibrio en la convivencia. | V13: ="{"&_xlfn.TEXTJOIN(",",TRUE, """"&_xlfn.TEXTJOIN(""":",TRUE,A$1,A13), """"&_xlfn.TEXTJOIN(""":""",TRUE,B$1,B13)&"""", """"&_xlfn.TEXTJOIN(""":""",TRUE,C$1,C13)&"""", """"&_xlfn.TEXTJOIN(""":""",TRUE,D$1,D13)&"""", """"&_xlfn.TEXTJOIN(""":",TRUE,E$1,E13), """"&_xlfn.TEXTJOIN(""":""",TRUE,F$1,F13)&"""", """"&_xlfn.TEXTJOIN(""":""",TRUE,G$1,G13)&"""", """"&_xlfn.TEXTJOIN(""":""",TRUE,H$1,H13)&"""", """"&_xlfn.TEXTJOIN(""":""",TRUE,I$1,I13)&"""", """"&_xlfn.TEXTJOIN(""":""",TRUE,J$1,J13)&"""", """"&_xlfn.TEXTJOIN(""":""",TRUE,K$1,K13)&"""", """"&_xlfn.TEXTJOIN(""":""",TRUE,L$1,L13)&"""", """"&_xlfn.TEXTJOIN(""":""",TRUE,M$1,M13)&"""", """"&_xlfn.TEXTJOIN(""":""",TRUE,N$1,N13)&"""", """"&_xlfn.TEXTJOIN(""":""",TRUE,O$1,O13)&"""", """"&_xlfn.TEXTJOIN(""":""",TRUE,P$1,P13)&"""", """"&_xlfn.TEXTJOIN(""":""",TRUE,Q$1,Q13)&"""", """"&_xlfn.TEXTJOIN(""":""",TRUE,R$1,R13)&"""", """"&_xlfn.TEXTJOIN(""":""",TRUE,S$1,S13)&"""", """"&_xlfn.TEXTJOIN(""":""",TRUE,T$1,T13)&"""", """"&_xlfn.TEXTJOIN(""":""",TRUE,U$1,U13)&"""" )&"}," -> {"Item":12,"Pregunta_I":" Comprendo por qué me siento como me siento","Nivel":"N2","CriterioN":"Procesamiento intermedio que regula y modula.","P_Invertida":false,"Conciencia":"Emocional","CriterioC":"Sensibilidad hacia los demás.","Impacto":"Medio","Pregunta":"¿Te resulta fácil entender la razón exacta de tu malestar o incomodidad cuando te encuentras en un entorno social?","R1":"Siento la incomodidad pero no logro entender por qué me ocurre.","R2":"Me cuesta mucho descifrar qué detonó mi malestar en ese momento.","R3":"A veces comprendo el origen de mi incomodidad tras pensarlo mucho.","R4":"Suelo identificar rápido qué situación o comentario me hizo sentir mal.","R5":"Reconozco de inmediato la causa exacta de mi emoción social.","Tipo de Respuesta":"Capacidad","T1":"Muy difícil","T2":"Dificil","T3":"Neutro","T4":"Facil","T5":"Muy fácil","Explicación":"Se enfoca en la comprensión emocional y su origen, clave para regulación social. Las respuestas miden el nivel de interpretación emocional y autoconocimiento, necesario para actuar con mayor equilibrio en la convivencia."}, | W13: =RAND() -> 0.070270616 | X13: =COUNTIFS($F$2:$F$200, F13, $W$2:$W$200, "<=" & W13) -> 1
... A151: 150 | B151: Me percibo como una persona íntegra | C151: N2 | D151: Procesamiento intermedio que regula y modula. | E151: false | F151: Coherencia Interna | G151: Asegura consistencia entre valores y acciones sociales. | H151: Alto | I151: ¿Qué tan de acuerdo estás con que la integridad es la característica que mejor define tu forma de actuar con los demás? | J151: No me considero una persona íntegra. | K151: Casi nunca actúo con integridad. | L151: Depende del contexto. | M151: Actúo con integridad. | N151: Siempre actúo con integridad, incluso cuando me cuesta. | O151: Actitud | P151: Totalmente en desacuerdo | Q151: En desacuerdo | R151: Ni de acuerdo ni en desacuerdo | S151: De acuerdo | T151: Totalmente de acuerdo | U151: Evalúa percepción interna de integridad como rasgo regulador del comportamiento social. | V151: ="{"&_xlfn.TEXTJOIN(",",TRUE, """"&_xlfn.TEXTJOIN(""":",TRUE,A$1,A151), """"&_xlfn.TEXTJOIN(""":""",TRUE,B$1,B151)&"""", """"&_xlfn.TEXTJOIN(""":""",TRUE,C$1,C151)&"""", """"&_xlfn.TEXTJOIN(""":""",TRUE,D$1,D151)&"""", """"&_xlfn.TEXTJOIN(""":",TRUE,E$1,E151), """"&_xlfn.TEXTJOIN(""":""",TRUE,F$1,F151)&"""", """"&_xlfn.TEXTJOIN(""":""",TRUE,G$1,G151)&"""", """"&_xlfn.TEXTJOIN(""":""",TRUE,H$1,H151)&"""", """"&_xlfn.TEXTJOIN(""":""",TRUE,I$1,I151)&"""", """"&_xlfn.TEXTJOIN(""":""",TRUE,J$1,J151)&"""", """"&_xlfn.TEXTJOIN(""":""",TRUE,K$1,K151)&"""", """"&_xlfn.TEXTJOIN(""":""",TRUE,L$1,L151)&"""", """"&_xlfn.TEXTJOIN(""":""",TRUE,M$1,M151)&"""", """"&_xlfn.TEXTJOIN(""":""",TRUE,N$1,N151)&"""", """"&_xlfn.TEXTJOIN(""":""",TRUE,O$1,O151)&"""", """"&_xlfn.TEXTJOIN(""":""",TRUE,P$1,P151)&"""", """"&_xlfn.TEXTJOIN(""":""",TRUE,Q$1,Q151)&"""", """"&_xlfn.TEXTJOIN(""":""",TRUE,R$1,R151)&"""", """"&_xlfn.TEXTJOIN(""":""",TRUE,S$1,S151)&"""", """"&_xlfn.TEXTJOIN(""":""",TRUE,T$1,T151)&"""", """"&_xlfn.TEXTJOIN(""":""",TRUE,U$1,U151)&"""" )&"}," -> {"Item":150,"Pregunta_I":" Me percibo como una persona íntegra","Nivel":"N2","CriterioN":"Procesamiento intermedio que regula y modula.","P_Invertida":false,"Conciencia":"Coherencia Interna","CriterioC":"Asegura consistencia entre valores y acciones sociales.","Impacto":"Alto","Pregunta":"¿Qué tan de acuerdo estás con que la integridad es la característica que mejor define tu forma de actuar con los demás?","R1":"No me considero una persona íntegra.","R2":"Casi nunca actúo con integridad.","R3":"Depende del contexto.","R4":"Actúo con integridad.","R5":"Siempre actúo con integridad, incluso cuando me cuesta.","Tipo de Respuesta":"Actitud","T1":"Totalmente en desacuerdo","T2":"En desacuerdo","T3":"Ni de acuerdo ni en desacuerdo","T4":"De acuerdo","T5":"Totalmente de acuerdo","Explicación":"Evalúa percepción interna de integridad como rasgo regulador del comportamiento social."}, | W151: =RAND() -> 0.68728952 | X151: =COUNTIFS($F$2:$F$200, F151, $W$2:$W$200, "<=" & W151) -> 7

Sheet 60 Preguntas
A1: Item | B1: Pregunta_I | C1: Nivel | D1: CriterioN | E1: P_Invertida | F1: Conciencia | G1: CriterioC | H1: Impacto | I1: Pregunta | J1: R1 | K1: R2 | L1: R3 | M1: R4 | N1: R5 | O1: Tipo de Respuesta | P1: T1 | Q1: T2 | R1: T3 | S1: T4 | T1: T5 | U1: Explicación | V1: Diccionarios
A2: 2 | B2: Cuestiono la información antes de aceptarla como verdadera | C2: N1 | D2: Fundamento interno que sostiene la conducta social. | E2: false | F2: Cognitiva | G2: Comprensión de problemas sociales. | H2: Medio | I2: ¿Cuestionas y verificas la veracidad de la información sobre problemas sociales antes de aceptarla como una verdad que guíe tu opinión o conducta? | J2: Acepto la información de forma automática. | K2: Solo dudo si la fuente me parece sospechosa. | L2: Comparo datos de vez en cuando antes de decidir. | M2: Suelo verificar la información en distintas fuentes. | N2: Evalúo críticamente toda información antes de creerla. | O2: Hábito | P2: Nunca | Q2: Casi nunca | R2: A veces | S2: Casi siempre | T2: Siempre | U2: La pregunta mide el hábito de pensamiento crítico aplicado al entorno social, especialmente frente a información compartida por otros. Evaluar este comportamiento es relevante porque influye en la forma en que el individuo procesa rumores, noticias o creencias sociales antes de reproducirlas. | V2: {"Item":2,"Pregunta_I":" Cuestiono la información antes de aceptarla como verdadera","Nivel":"N1","CriterioN":"Fundamento interno que sostiene la conducta social.","P_Invertida":false,"Conciencia":"Cognitiva","CriterioC":"Comprensión de problemas sociales.","Impacto":"Medio","Pregunta":"¿Cuestionas y verificas la veracidad de la información sobre problemas sociales antes de aceptarla como una verdad que guíe tu opinión o conducta?","R1":"Acepto la información de forma automática.","R2":"Solo dudo si la fuente me parece sospechosa.","R3":"Comparo datos de vez en cuando antes de decidir.","R4":"Suelo verificar la información en distintas fuentes.","R5":"Evalúo críticamente toda información antes de creerla.","Tipo de Respuesta":"Hábito","T1":"Nunca","T2":"Casi nunca","T3":"A veces","T4":"Casi siempre","T5":"Siempre","Explicación":"La pregunta mide el hábito de pensamiento crítico aplicado al entorno social, especialmente frente a información compartida por otros. Evaluar este comportamiento es relevante porque influye en la forma en que el individuo procesa rumores, noticias o creencias sociales antes de reproducirlas."},
A3: 4 | B3: Identifico errores en mi razonamiento | C3: N1 | D3: Fundamento interno que sostiene la conducta social. | E3: false | F3: Cognitiva | G3: Comprensión de problemas sociales. | H3: Medio | I3: ¿Te resulta fácil detectar una falla o contradicción en tu propia forma de pensar cuando analizas un problema social complejo? | J3: No logro ver errores en mi lógica. | K3: Me cuesta mucho aceptar que mi razonamiento puede estar equivocado. | L3: A veces noto mis errores, pero solo después de que alguien me los señala. | M3: Suelo identificar mis propias contradicciones mientras estoy reflexionando. | N3: Detecto y corrijo mis fallos de razonamiento de manera natural y constante. | O3: Capacidad | P3: Muy difícil | Q3: Dificil | R3: Neutro | S3: Facil | T3: Muy fácil | U3: Esta formulación sitúa la reflexión interna dentro de un conflicto interpersonal, permitiendo medir la capacidad de autocontrol cognitivo antes de responder socialmente. Se evalúa qué tan fácil es para el individuo detenerse, analizar y responder con conciencia en interacción con otros. | V3: {"Item":4,"Pregunta_I":" Identifico errores en mi razonamiento","Nivel":"N1","CriterioN":"Fundamento interno que sostiene la conducta social.","P_Invertida":false,"Conciencia":"Cognitiva","CriterioC":"Comprensión de problemas sociales.","Impacto":"Medio","Pregunta":"¿Te resulta fácil detectar una falla o contradicción en tu propia forma de pensar cuando analizas un problema social complejo?","R1":"No logro ver errores en mi lógica.","R2":"Me cuesta mucho aceptar que mi razonamiento puede estar equivocado.","R3":"A veces noto mis errores, pero solo después de que alguien me los señala.","R4":"Suelo identificar mis propias contradicciones mientras estoy reflexionando.","R5":"Detecto y corrijo mis fallos de razonamiento de manera natural y constante.","Tipo de Respuesta":"Capacidad","T1":"Muy difícil","T2":"Dificil","T3":"Neutro","T4":"Facil","T5":"Muy fácil","Explicación":"Esta formulación sitúa la reflexión interna dentro de un conflicto interpersonal, permitiendo medir la capacidad de autocontrol cognitivo antes de responder socialmente. Se evalúa qué tan fácil es para el individuo detenerse, analizar y responder con conciencia en interacción con otros."},
A4: 6 | B4: Cambio de opinión cuando la evidencia lo justifica | C4: N1 | D4: Fundamento interno que sostiene la conducta social. | E4: false | F4: Cognitiva | G4: Comprensión de problemas sociales. | H4: Medio | I4: ¿Qué tan de acuerdo estás con la práctica de modificar tu postura sobre un problema social cuando se te presenta evidencia lógica que demuestra que tu opinión inicial era incorrecta? | J4: Mantengo mi posición inicial aunque me presenten pruebas en contra. | K4: Me cuesta mucho aceptar que estoy equivocado y cambiar mi discurso. | L4: Solo cambio de opinión si la evidencia es abrumadora o me afecta. | M4: Estoy dispuesto a ajustar mis ideas si me demuestran que hay datos más válidos. | N4: Priorizo la verdad y la lógica sobre el hecho de tener la razón. | O4: Acuerdo | P4: Totalmente en desacuerdo | Q4: En desacuerdo | R4: Ni de acuerdo ni en desacuerdo | S4: De acuerdo | T4: Totalmente de acuerdo | U4: La pregunta evalúa el nivel de acuerdo con la capacidad de ajustar creencias cuando existen argumentos sólidos. Esto permite medir apertura cognitiva y disposición al cambio racional, habilidades esenciales para la toma de decisiones responsables dentro de dinámicas sociales. | V4: {"Item":6,"Pregunta_I":" Cambio de opinión cuando la evidencia lo justifica","Nivel":"N1","CriterioN":"Fundamento interno que sostiene la conducta social.","P_Invertida":false,"Conciencia":"Cognitiva","CriterioC":"Comprensión de problemas sociales.","Impacto":"Medio","Pregunta":"¿Qué tan de acuerdo estás con la práctica de modificar tu postura sobre un problema social cuando se te presenta evidencia lógica que demuestra que tu opinión inicial era incorrecta?","R1":"Mantengo mi posición inicial aunque me presenten pruebas en contra.","R2":"Me cuesta mucho aceptar que estoy equivocado y cambiar mi discurso.","R3":"Solo cambio de opinión si la evidencia es abrumadora o me afecta.","R4":"Estoy dispuesto a ajustar mis ideas si me demuestran que hay datos más válidos.","R5":"Priorizo la verdad y la lógica sobre el hecho de tener la razón.","Tipo de Respuesta":"Acuerdo","T1":"Totalmente en desacuerdo","T2":"En desacuerdo","T3":"Ni de acuerdo ni en desacuerdo","T4":"De acuerdo","T5":"Totalmente de acuerdo","Explicación":"La pregunta evalúa el nivel de acuerdo con la capacidad de ajustar creencias cuando existen argumentos sólidos. Esto permite medir apertura cognitiva y disposición al cambio racional, habilidades esenciales para la toma de decisiones responsables dentro de dinámicas sociales."},
A5: 10 | B5: Me cuesta estructurar mis pensamientos | C5: N1 | D5: Fundamento interno que sostiene la conducta social. | E5: true | F5: Cognitiva | G5: Comprensión de problemas sociales. | H5: Medio | I5: ¿Te resulta fácil sentir que tus pensamientos sobre un tema social están desordenados o te cuesta darles una estructura clara? | J5: Mis pensamientos siempre están ordenados y claros. | K5: Logro estructurar bien mis ideas. | L5: A veces me confundo con tanta información. | M5: Frecuentemente me cuesta organizar lo que pienso. | N5: Mis ideas suelen ser un caos y no logro ordenarlas. | O5: Capacidad | P5: Muy difícil | Q5: Dificil | R5: Neutro | S5: Facil | T5: Muy fácil | U5: La pregunta evalúa la dificultad para estructurar pensamientos al comunicarse socialmente, enfocándose en la claridad mental aplicada a la interacción con otros. Al ser una pregunta invertida, permite detectar limitaciones cognitivas en expresión y coherencia verbal en contextos colectivos. | V5: {"Item":10,"Pregunta_I":" Me cuesta estructurar mis pensamientos","Nivel":"N1","CriterioN":"Fundamento interno que sostiene la conducta social.","P_Invertida":true,"Conciencia":"Cognitiva","CriterioC":"Comprensión de problemas sociales.","Impacto":"Medio","Pregunta":"¿Te resulta fácil sentir que tus pensamientos sobre un tema social están desordenados o te cuesta darles una estructura clara?","R1":"Mis pensamientos siempre están ordenados y claros.","R2":"Logro estructurar bien mis ideas.","R3":"A veces me confundo con tanta información.","R4":"Frecuentemente me cuesta organizar lo que pienso.","R5":"Mis ideas suelen ser un caos y no logro ordenarlas.","Tipo de Respuesta":"Capacidad","T1":"Muy difícil","T2":"Dificil","T3":"Neutro","T4":"Facil","T5":"Muy fácil","Explicación":"La pregunta evalúa la dificultad para estructurar pensamientos al comunicarse socialmente, enfocándose en la claridad mental aplicada a la interacción con otros. Al ser una pregunta invertida, permite detectar limitaciones cognitivas en expresión y coherencia verbal en contextos colectivos."},
A6: 12 | B6: Comprendo por qué me siento como me siento | C6: N2 | D6: Procesamiento intermedio que regula y modula. | E6: false | F6: Emocional | G6: Sensibilidad hacia los demás. | H6: Medio | I6: ¿Te resulta fácil entender la razón exacta de tu malestar o incomodidad cuando te encuentras en un entorno social? | J6: Siento la incomodidad pero no logro entender por qué me ocurre. | K6: Me cuesta mucho descifrar qué detonó mi malestar en ese momento. | L6: A veces comprendo el origen de mi incomodidad tras pensarlo mucho. | M6: Suelo identificar rápido qué situación o comentario me hizo sentir mal. | N6: Reconozco de inmediato la causa exacta de mi emoción social. | O6: Capacidad | P6: Muy difícil | Q6: Dificil | R6: Neutro | S6: Facil | T6: Muy fácil | U6: Se enfoca en la comprensión emocional y su origen, clave para regulación social. Las respuestas miden el nivel de interpretación emocional y autoconocimiento, necesario para actuar con mayor equilibrio en la convivencia. | V6: {"Item":12,"Pregunta_I":" Comprendo por qué me siento como me siento","Nivel":"N2","CriterioN":"Procesamiento intermedio que regula y modula.","P_Invertida":false,"Conciencia":"Emocional","CriterioC":"Sensibilidad hacia los demás.","Impacto":"Medio","Pregunta":"¿Te resulta fácil entender la razón exacta de tu malestar o incomodidad cuando te encuentras en un entorno social?","R1":"Siento la incomodidad pero no logro entender por qué me ocurre.","R2":"Me cuesta mucho descifrar qué detonó mi malestar en ese momento.","R3":"A veces comprendo el origen de mi incomodidad tras pensarlo mucho.","R4":"Suelo identificar rápido qué situación o comentario me hizo sentir mal.","R5":"Reconozco de inmediato la causa exacta de mi emoción social.","Tipo de Respuesta":"Capacidad","T1":"Muy difícil","T2":"Dificil","T3":"Neutro","T4":"Facil","T5":"Muy fácil","Explicación":"Se enfoca en la comprensión emocional y su origen, clave para regulación social. Las respuestas miden el nivel de interpretación emocional y autoconocimiento, necesario para actuar con mayor equilibrio en la convivencia."},
A7: 13 | B7: Expreso mis emociones de forma adecuada | C7: N3 | D7: Manifestación externa observable en la sociedad. | E7: false | F7: Emocional | G7: Sensibilidad hacia los demás. | H7: Medio | I7: ¿Te resulta fácil expresar tus emociones de manera tranquila y clara ante los demás, incluso cuando te sientes molesto o incómodo? | J7: No logro expresarlas; o exploto o me guardo todo. | K7: Me cuesta mucho encontrar las palabras o el tono adecuado. | L7: A veces me expreso bien, pero pierdo el control si hay presión. | M7: Suelo comunicar lo que siento sin herir a los demás. | N7: Expreso mis sentimientos con total asertividad y calma siempre. | O7: Capacidad | P7: Muy difícil | Q7: Dificil | R7: Neutro | S7: Facil | T7: Muy fácil | U7: Se reformula para medir expresión emocional observable en sociedad. Las respuestas representan niveles de control y comunicación emocional, reflejando cómo el individuo maneja sus emociones en interacción con otros. | V7: {"Item":13,"Pregunta_I":" Expreso mis emociones de forma adecuada","Nivel":"N3","CriterioN":"Manifestación externa observable en la sociedad.","P_Invertida":false,"Conciencia":"Emocional","CriterioC":"Sensibilidad hacia los demás.","Impacto":"Medio","Pregunta":"¿Te resulta fácil expresar tus emociones de manera tranquila y clara ante los demás, incluso cuando te sientes molesto o incómodo?","R1":"No logro expresarlas; o exploto o me guardo todo.","R2":"Me cuesta mucho encontrar las palabras o el tono adecuado.","R3":"A veces me expreso bien, pero pierdo el control si hay presión.","R4":"Suelo comunicar lo que siento sin herir a los demás.","R5":"Expreso mis sentimientos con total asertividad y calma siempre.","Tipo de Respuesta":"Capacidad","T1":"Muy difícil","T2":"Dificil","T3":"Neutro","T4":"Facil","T5":"Muy fácil","Explicación":"Se reformula para medir expresión emocional observable en sociedad. Las respuestas representan niveles de control y comunicación emocional, reflejando cómo el individuo maneja sus emociones en interacción con otros."},
A8: 15 | B8: Me desbordo fácilmente emocionalmente | C8: N2 | D8: Procesamiento intermedio que regula y modula. | E8: true | F8: Emocional | G8: Sensibilidad hacia los demás. | H8: Medio | I8: ¿Sientes que tus emociones te sobrepasan o te desbordan, impidiéndote reaccionar de forma equilibrada ante los demás? | J8: Mantengo siempre el equilibrio, sin importar la intensidad emocional. | K8: Logro modular mis emociones antes de que me superen. | L8: En situaciones de mucha presión, pierdo mi centro emocional. | M8: Suelo sentirme desbordado y me cuesta recuperar la calma. | N8: Mis emociones me dominan totalmente y pierdo el control con facilidad. | O8: Frecuencia emocional | P8: Nunca | Q8: Casi nunca | R8: A veces | S8: Casi siempre | T8: Siempre | U8: La pregunta se mantiene como conducta emocional desbordada en contexto social. Es invertida porque representa dificultad de regulación emocional. Las respuestas reflejan niveles de control emocional frente a presión social. | V8: {"Item":15,"Pregunta_I":" Me desbordo fácilmente emocionalmente","Nivel":"N2","CriterioN":"Procesamiento intermedio que regula y modula.","P_Invertida":true,"Conciencia":"Emocional","CriterioC":"Sensibilidad hacia los demás.","Impacto":"Medio","Pregunta":"¿Sientes que tus emociones te sobrepasan o te desbordan, impidiéndote reaccionar de forma equilibrada ante los demás?","R1":"Mantengo siempre el equilibrio, sin importar la intensidad emocional.","R2":"Logro modular mis emociones antes de que me superen.","R3":"En situaciones de mucha presión, pierdo mi centro emocional.","R4":"Suelo sentirme desbordado y me cuesta recuperar la calma.","R5":"Mis emociones me dominan totalmente y pierdo el control con facilidad.","Tipo de Respuesta":"Frecuencia emocional","T1":"Nunca","T2":"Casi nunca","T3":"A veces","T4":"Casi siempre","T5":"Siempre","Explicación":"La pregunta se mantiene como conducta emocional desbordada en contexto social. Es invertida porque representa dificultad de regulación emocional. Las respuestas reflejan niveles de control emocional frente a presión social."},
